============================================================================================== 
Warning! Mixing Conda and module environments may lead to corruption of the
user environment. 
We do not recommend users mixing those two environments unless absolutely
necessary. Note that 
SURF does not provide any support for Conda environment.
For more information, please refer to our software policy page:
https://servicedesk.surf.nl/wiki/display/WIKI/Software+policy+Snellius#SoftwarepolicySnellius-UseofAnacondaandMinicondaenvironmentsonSnellius 

Remember that many packages have already been installed on the system and can
be loaded using 
the 'module load <package__name>' command. If you are uncertain if a package is
already available 
on the system, please use 'module avail' or 'module spider' to search for it.
============================================================================================== 
# conda environments:
#
thesis-env               /home/lknigge/.conda/envs/thesis-env
base                     /sw/arch/RHEL8/EB_production/2023/software/Anaconda3/2023.07-2

/home/lknigge/.conda/envs/thesis-env/lib/python3.12/site-packages/torch/cuda/__init__.py:619: UserWarning: Can't initialize NVML
  warnings.warn("Can't initialize NVML")
/home/lknigge/augmented_llm_playground_fabian/outputs/debug
[2025-02-20 12:28:05,120][root][INFO] - Verbose output.
2025/02/20 12:28:05 WARNING mlflow.system_metrics.system_metrics_monitor: Skip logging GPU metrics because creating `GPUMonitor` failed with error: Failed to initialize NVML, skip logging GPU metrics: Driver Not Loaded.
2025/02/20 12:28:05 INFO mlflow.system_metrics.system_metrics_monitor: Started monitoring system metrics.
[2025-02-20 12:28:05,237][sentence_transformers.SentenceTransformer][INFO] - Use pytorch device_name: cpu
[2025-02-20 12:28:05,237][sentence_transformers.SentenceTransformer][INFO] - Load pretrained SentenceTransformer: all-MiniLM-L6-v2
/home/lknigge/.conda/envs/thesis-env/lib/python3.12/site-packages/huggingface_hub/file_download.py:797: FutureWarning: `resume_download` is deprecated and will be removed in version 1.0.0. Downloads always resume when possible. If you want to force a new download, use `force_download=True`.
  warnings.warn(
Batches:   0%|          | 0/6 [00:00<?, ?it/s]Batches:  17%|â–ˆâ–‹        | 1/6 [00:00<00:00,  6.96it/s]Batches:  50%|â–ˆâ–ˆâ–ˆâ–ˆâ–ˆ     | 3/6 [00:00<00:00, 10.29it/s]Batches:  83%|â–ˆâ–ˆâ–ˆâ–ˆâ–ˆâ–ˆâ–ˆâ–ˆâ–Ž | 5/6 [00:00<00:00, 12.82it/s]Batches: 100%|â–ˆâ–ˆâ–ˆâ–ˆâ–ˆâ–ˆâ–ˆâ–ˆâ–ˆâ–ˆ| 6/6 [00:00<00:00, 13.18it/s]
{'file_name': '/home/lknigge/augmented_llm_playground_fabian/data/LogicBench/abducted_data/binary/fol_eval_debug.jsonl', 'prompt_dir': '/home/lknigge/augmented_llm_playground_fabian/jam/prompts/logicbench', '_target_': 'jam.datasets.LogicBench'}
/home/lknigge/augmented_llm_playground_fabian
ok
/home/lknigge/augmented_llm_playground_fabian/data/LogicBench/abducted_data/binary/fol_eval_debug.jsonl
test10
test
  0%|          | 0/1 [00:00<?, ?it/s]
Batches:   0%|          | 0/1 [00:00<?, ?it/s][A
Batches: 100%|â–ˆâ–ˆâ–ˆâ–ˆâ–ˆâ–ˆâ–ˆâ–ˆâ–ˆâ–ˆ| 1/1 [00:00<00:00,  9.67it/s][ABatches: 100%|â–ˆâ–ˆâ–ˆâ–ˆâ–ˆâ–ˆâ–ˆâ–ˆâ–ˆâ–ˆ| 1/1 [00:00<00:00,  9.65it/s]
[2025-02-20 12:28:07,611][openai._base_client][INFO] - Retrying request to /chat/completions in 0.496758 seconds
[2025-02-20 12:28:08,114][openai._base_client][INFO] - Retrying request to /chat/completions in 0.900496 seconds
  0%|          | 0/1 [00:01<?, ?it/s]
2025/02/20 12:28:09 WARNING mlflow.tracing.export.mlflow: Failed to log trace to MLflow backend. Error: [Errno 13] Permission denied: '/lknigge'. For full traceback, set logging level to debug.
2025/02/20 12:28:09 INFO mlflow.system_metrics.system_metrics_monitor: Stopping system metrics monitoring...
2025/02/20 12:28:09 INFO mlflow.system_metrics.system_metrics_monitor: Successfully terminated system metrics monitoring!
Error executing job with overrides: []
Traceback (most recent call last):
  File "/home/lknigge/.conda/envs/thesis-env/lib/python3.12/site-packages/httpx/_transports/default.py", line 101, in map_httpcore_exceptions
    yield
  File "/home/lknigge/.conda/envs/thesis-env/lib/python3.12/site-packages/httpx/_transports/default.py", line 250, in handle_request
    resp = self._pool.handle_request(req)
           ^^^^^^^^^^^^^^^^^^^^^^^^^^^^^^
  File "/home/lknigge/.conda/envs/thesis-env/lib/python3.12/site-packages/httpcore/_sync/connection_pool.py", line 256, in handle_request
    raise exc from None
  File "/home/lknigge/.conda/envs/thesis-env/lib/python3.12/site-packages/httpcore/_sync/connection_pool.py", line 236, in handle_request
    response = connection.handle_request(
               ^^^^^^^^^^^^^^^^^^^^^^^^^^
  File "/home/lknigge/.conda/envs/thesis-env/lib/python3.12/site-packages/httpcore/_sync/connection.py", line 103, in handle_request
    return self._connection.handle_request(request)
           ^^^^^^^^^^^^^^^^^^^^^^^^^^^^^^^^^^^^^^^^
  File "/home/lknigge/.conda/envs/thesis-env/lib/python3.12/site-packages/httpcore/_sync/http11.py", line 136, in handle_request
    raise exc
  File "/home/lknigge/.conda/envs/thesis-env/lib/python3.12/site-packages/httpcore/_sync/http11.py", line 86, in handle_request
    self._send_request_headers(**kwargs)
  File "/home/lknigge/.conda/envs/thesis-env/lib/python3.12/site-packages/httpcore/_sync/http11.py", line 144, in _send_request_headers
    with map_exceptions({h11.LocalProtocolError: LocalProtocolError}):
  File "/home/lknigge/.conda/envs/thesis-env/lib/python3.12/contextlib.py", line 158, in __exit__
    self.gen.throw(value)
  File "/home/lknigge/.conda/envs/thesis-env/lib/python3.12/site-packages/httpcore/_exceptions.py", line 14, in map_exceptions
    raise to_exc(exc) from exc
httpcore.LocalProtocolError: Illegal header value b'Bearer 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\r'

The above exception was the direct cause of the following exception:

Traceback (most recent call last):
  File "/home/lknigge/.conda/envs/thesis-env/lib/python3.12/site-packages/openai/_base_client.py", line 1003, in _request
    response = self._client.send(
               ^^^^^^^^^^^^^^^^^^
  File "/home/lknigge/.conda/envs/thesis-env/lib/python3.12/site-packages/httpx/_client.py", line 914, in send
    response = self._send_handling_auth(
               ^^^^^^^^^^^^^^^^^^^^^^^^^
  File "/home/lknigge/.conda/envs/thesis-env/lib/python3.12/site-packages/httpx/_client.py", line 942, in _send_handling_auth
    response = self._send_handling_redirects(
               ^^^^^^^^^^^^^^^^^^^^^^^^^^^^^^
  File "/home/lknigge/.conda/envs/thesis-env/lib/python3.12/site-packages/httpx/_client.py", line 979, in _send_handling_redirects
    response = self._send_single_request(request)
               ^^^^^^^^^^^^^^^^^^^^^^^^^^^^^^^^^^
  File "/home/lknigge/.conda/envs/thesis-env/lib/python3.12/site-packages/httpx/_client.py", line 1014, in _send_single_request
    response = transport.handle_request(request)
               ^^^^^^^^^^^^^^^^^^^^^^^^^^^^^^^^^
  File "/home/lknigge/.conda/envs/thesis-env/lib/python3.12/site-packages/httpx/_transports/default.py", line 249, in handle_request
    with map_httpcore_exceptions():
  File "/home/lknigge/.conda/envs/thesis-env/lib/python3.12/contextlib.py", line 158, in __exit__
    self.gen.throw(value)
  File "/home/lknigge/.conda/envs/thesis-env/lib/python3.12/site-packages/httpx/_transports/default.py", line 118, in map_httpcore_exceptions
    raise mapped_exc(message) from exc
httpx.LocalProtocolError: Illegal header value b'Bearer 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\r'

The above exception was the direct cause of the following exception:

Traceback (most recent call last):
  File "/gpfs/home4/lknigge/augmented_llm_playground_fabian/evaluate.py", line 130, in main
    run_evaluation_loop(model, config.datasets[0], config.batch_size)
  File "/gpfs/home4/lknigge/augmented_llm_playground_fabian/evaluate.py", line 52, in run_evaluation_loop
    predictions, steps = model.predict(batch["context"], batch["query"])
                         ^^^^^^^^^^^^^^^^^^^^^^^^^^^^^^^^^^^^^^^^^^^^^^^
  File "/gpfs/home4/lknigge/augmented_llm_playground_fabian/jam/langgraph_rag.py", line 286, in predict
    result = self.app.invoke({"context": c, "query": q, })
             ^^^^^^^^^^^^^^^^^^^^^^^^^^^^^^^^^^^^^^^^^^^^^
  File "/home/lknigge/.conda/envs/thesis-env/lib/python3.12/site-packages/langgraph/pregel/__init__.py", line 2124, in invoke
    for chunk in self.stream(
  File "/home/lknigge/.conda/envs/thesis-env/lib/python3.12/site-packages/langgraph/pregel/__init__.py", line 1779, in stream
    for _ in runner.tick(
  File "/home/lknigge/.conda/envs/thesis-env/lib/python3.12/site-packages/langgraph/pregel/runner.py", line 230, in tick
    run_with_retry(
  File "/home/lknigge/.conda/envs/thesis-env/lib/python3.12/site-packages/langgraph/pregel/retry.py", line 40, in run_with_retry
    return task.proc.invoke(task.input, config)
           ^^^^^^^^^^^^^^^^^^^^^^^^^^^^^^^^^^^^
  File "/home/lknigge/.conda/envs/thesis-env/lib/python3.12/site-packages/langgraph/utils/runnable.py", line 546, in invoke
    input = step.invoke(input, config, **kwargs)
            ^^^^^^^^^^^^^^^^^^^^^^^^^^^^^^^^^^^^
  File "/home/lknigge/.conda/envs/thesis-env/lib/python3.12/site-packages/langgraph/utils/runnable.py", line 310, in invoke
    ret = context.run(self.func, *args, **kwargs)
          ^^^^^^^^^^^^^^^^^^^^^^^^^^^^^^^^^^^^^^^
  File "/gpfs/home4/lknigge/augmented_llm_playground_fabian/jam/langgraph_rag.py", line 188, in generate_draft
    generated_texts = mlflow.trace(self.lm.generate,span_type="LLM")(input_texts)[0] # LLM generates list, but intput is only one
                      ^^^^^^^^^^^^^^^^^^^^^^^^^^^^^^^^^^^^^^^^^^^^^^^^^^^^^^^^^^^
  File "/home/lknigge/.conda/envs/thesis-env/lib/python3.12/site-packages/mlflow/tracing/fluent.py", line 174, in wrapper
    with _WrappingContext(fn, args, kwargs) as wrapping_coro:
  File "/home/lknigge/.conda/envs/thesis-env/lib/python3.12/site-packages/mlflow/tracing/fluent.py", line 162, in __exit__
    self.coro.throw(exc_type, exc_value, traceback)
  File "/home/lknigge/.conda/envs/thesis-env/lib/python3.12/site-packages/mlflow/tracing/fluent.py", line 145, in _wrapping_logic
    result = yield  # sync/async function output to be sent here
             ^^^^^
  File "/home/lknigge/.conda/envs/thesis-env/lib/python3.12/site-packages/mlflow/tracing/fluent.py", line 175, in wrapper
    return wrapping_coro.send(fn(*args, **kwargs))
                              ^^^^^^^^^^^^^^^^^^^
  File "/gpfs/home4/lknigge/augmented_llm_playground_fabian/jam/language_models/open_ai_api.py", line 76, in generate
    print(self.create_fn(messages = prompt[0], client=client))
          ^^^^^^^^^^^^^^^^^^^^^^^^^^^^^^^^^^^^^^^^^^^^^^^^^^^
  File "/home/lknigge/.conda/envs/thesis-env/lib/python3.12/site-packages/backoff/_sync.py", line 105, in retry
    ret = target(*args, **kwargs)
          ^^^^^^^^^^^^^^^^^^^^^^^
  File "/gpfs/home4/lknigge/augmented_llm_playground_fabian/jam/language_models/open_ai_api.py", line 46, in <lambda>
    self.create_fn = backoff.on_exception(backoff.expo, openai.RateLimitError, max_time=100, jitter=backoff.full_jitter,)( lambda messages, client : client.chat.completions.create(messages=messages, model=self.model_name, max_tokens=self.max_token, temperature=self.temperature, stop=self.stop_list))
                                                                                                                                                     ^^^^^^^^^^^^^^^^^^^^^^^^^^^^^^^^^^^^^^^^^^^^^^^^^^^^^^^^^^^^^^^^^^^^^^^^^^^^^^^^^^^^^^^^^^^^^^^^^^^^^^^^^^^^^^^^^^^^^^^^^^^^^^^^^^^^^^^^^^^^^^^^^^^^^^
  File "/home/lknigge/.conda/envs/thesis-env/lib/python3.12/site-packages/openai/_utils/_utils.py", line 279, in wrapper
    return func(*args, **kwargs)
           ^^^^^^^^^^^^^^^^^^^^^
  File "/home/lknigge/.conda/envs/thesis-env/lib/python3.12/site-packages/openai/resources/chat/completions/completions.py", line 879, in create
    return self._post(
           ^^^^^^^^^^^
  File "/home/lknigge/.conda/envs/thesis-env/lib/python3.12/site-packages/openai/_base_client.py", line 1290, in post
    return cast(ResponseT, self.request(cast_to, opts, stream=stream, stream_cls=stream_cls))
                           ^^^^^^^^^^^^^^^^^^^^^^^^^^^^^^^^^^^^^^^^^^^^^^^^^^^^^^^^^^^^^^^^^
  File "/home/lknigge/.conda/envs/thesis-env/lib/python3.12/site-packages/openai/_base_client.py", line 967, in request
    return self._request(
           ^^^^^^^^^^^^^^
  File "/home/lknigge/.conda/envs/thesis-env/lib/python3.12/site-packages/openai/_base_client.py", line 1027, in _request
    return self._retry_request(
           ^^^^^^^^^^^^^^^^^^^^
  File "/home/lknigge/.conda/envs/thesis-env/lib/python3.12/site-packages/openai/_base_client.py", line 1105, in _retry_request
    return self._request(
           ^^^^^^^^^^^^^^
  File "/home/lknigge/.conda/envs/thesis-env/lib/python3.12/site-packages/openai/_base_client.py", line 1027, in _request
    return self._retry_request(
           ^^^^^^^^^^^^^^^^^^^^
  File "/home/lknigge/.conda/envs/thesis-env/lib/python3.12/site-packages/openai/_base_client.py", line 1105, in _retry_request
    return self._request(
           ^^^^^^^^^^^^^^
  File "/home/lknigge/.conda/envs/thesis-env/lib/python3.12/site-packages/openai/_base_client.py", line 1037, in _request
    raise APIConnectionError(request=request) from err
openai.APIConnectionError: Connection error.
During task with name 'draft' and id 'bcea0c5c-4f54-a9e6-5773-89f2b068d0b0'

Set the environment variable HYDRA_FULL_ERROR=1 for a complete stack trace.
srun: error: tcn451: task 0: Exited with exit code 1
srun: Terminating StepId=10091752.0

JOB STATISTICS
==============
Job ID: 10091752
Cluster: snellius
User/Group: lknigge/lknigge
State: FAILED (exit code 1)
Nodes: 1
Cores per node: 16
CPU Utilized: 00:00:16
CPU Efficiency: 3.45% of 00:07:44 core-walltime
Job Wall-clock time: 00:00:29
Memory Utilized: 2.12 MB
Memory Efficiency: 0.01% of 28.00 GB
